Workbook

Sheet 1. RG-RQ
B1: Research Goal
B2: Purpose | C2: Collection and comparison of studies on
B3: Issue | C3: model-driven approaches that explicitly address the software architecture of
B4: Object | C4: artificial intelligence applications (machine learning, deep learning)
B5: Viewpoint | C5: from the point of view of researchers
B7: Based on:
B8: Caldiera, V. R. B. G., & Rombach, H. D. (1994). The goal question metric approach. Encyclopedia of software engineering, 528-532.
A13: ID | B13: Research Question | C13: Motivation
A14: RQ1 | B14: What language aspects of MDE are addressed in the approaches, e.g., abstract syntax, concrete syntax, metamodel, etc.? | C14: This RQ aims to assess the pillar concepts of MDE languages concerning comprehensiveness (of modeling) and applicability (maturity).
A15: RQ2 | B15: Which phases of AI development aligned with the CRISP-DM methodology are covered by the approaches? | C15: This RQ assesses the extent to which the development phases of CRISP-DM are covered. As a result, implications can be made about the extent of support.
A16: RQ3 | B16: Which industrial domains are supported by MDE for AI approaches? | C16: This RQ enables finding industries that are using MDE in the context of AI and thus driving the development of MDE for AI using domain-specific tools and methodologies towards the needs of the (specific) industry.
A17: RQ4 | B17: What are the used methods and MDE tools the proposed approaches~rely on? | C17: This RQ allows assessing the underlying principles of methods used, e.g. SysML or MDE methods and the related toolchain such as WebGME. Consequently, further development can rely on these technologies to gain maturity instead of reinventing the wheel.
A18: RQ5 | B18: To what extent is communication between different stakeholders supported by MDE? | C18: Communication and business knowledge elaboration are one of the core pitfalls in the development of AI solutions \cite{piorkowski_how_2021}. Therefore, this question aims to assess the contribution to support fostering AI in the industry.
A19: RQ6 | B19: Which challenges and research directions are still open? | C19: This RQ will lead to future research directions and challenges for the model-based engineering of artificial intelligence applications due to a collection of limitations in the proposed approaches based on respective authors or our obtainment.

Sheet 2. Search Queries
E1: Databases Nr. of results
A2: ID | B2: Part 1 | D2: Part 2 | E2: IEEExplore | F2: ACM | G2: Springer | H2: DBLP | I2: Google Scholar
A3: SS1 | B3: MDE | C3: AND | D3: AI | E3: 5 | F3: 4 | G3: 6 | H3: 8 | I3: 0
A4: SS2 | B4: Model-Driven Engineering | C4: AND | D4: AI | E4: 8 | F4: 5 | G4: 15 | H4: 9 | I4: 6
A5: SS3 | B5: DSL | C5: AND | D5: AI | E5: 5 | F5: 4 | G5: 17 | H5: 1 | I5: 3
A6: SS4 | B6: Domain Specific Language | C6: AND | D6: AI | E6: 4 | F6: 3 | G6: 5 | H6: 6 | I6: 1
A7: SS5 | B7: Metamodeling | C7: AND | D7: AI | E7: 2 | F7: 1 | G7: 16 | H7: 3 | I7: 1
A8: SS6 | B8: Domain Modeling | C8: AND | D8: AI | E8: 1 | F8: 3 | G8: 12 | H8: 7 | I8: 2
A9: SS7 | B9: MDE | C9: AND | D9: Artificial Intelligence | E9: 5 | F9: 3 | G9: 31 | H9: 2 | I9: 2
A10: SS8 | B10: Model-Driven Engineering | C10: AND | D10: Artificial Intelligence | E10: 10 | F10: 9 | G10: 65 | H10: 4 | I10: 4
A11: SS9 | B11: DSL | C11: AND | D11: Artificial Intelligence | E11: 6 | F11: 2 | G11: 56 | H11: 1 | I11: 1
A12: SS10 | B12: Domain Specific Language | C12: AND | D12: Artificial Intelligence | E12: 8 | F12: 3 | G12: 45 | H12: 0 | I12: 2
A13: SS11 | B13: Metamodeling | C13: AND | D13: Artificial Intelligence | E13: 1 | F13: 1 | G13: 55 | H13: 0 | I13: 1
A14: SS12 | B14: Domain Modeling | C14: AND | D14: Artificial Intelligence | E14: 2 | F14: 2 | G14: 28 | H14: 2 | I14: 1
... A38: SS36 | B38: Domain Modeling | C38: AND | D38: Intelligence | E38: 3 | F38: 2 | G38: 31 | H38: 3 | I38: 1
E39: =SUM(E3:E38) -> 252 | F39: =SUM(F3:F38) -> 155 | G39: =SUM(G3:G38) -> 827 | H39: =SUM(H3:H38) -> 102 | I39: =SUM(I3:I38) -> 92
D40: Unique: | E40: 137 | F40: 83 | G40: 408 | H40: 81 | I40: 74

Sheet 3. Unique Results
A1: Key | B1: Item Type | C1: Publication Year | D1: Author | E1: Title | F1: Publication Title | G1: ISBN | H1: ISSN | I1: DOI | J1: Url | K1: Date | L1: Date Added | M1: Date Modified | N1: Access Date | O1: Pages | P1: Issue | Q1: Volume | R1: Journal Abbreviation | S1: Short Title | T1: Publisher | U1: Place | V1: Language | W1: Library Catalog | X1: Extra | Y1: Editor | Z1: Series Editor
A2: NGEXAYY3 | B2: journalArticle | C2: 2018 | D2: Zheng, Jun | E2: An output mapping variable fidelity metamodeling approach based on nested Latin hypercube design for complex engineering design optimization | F2: Applied Intelligence | H2: 0924-669X, 1573-7497 | I2: 10.1007/s10489-018-1164-8 | J2: http://link.springer.com/10.1007/s10489-018-1164-8 | K2: 2018-10 | L2: 44887.364 | M2: 44887.364 | N2: 44886.598 | O2: 3591-3611 | P2: 10 | Q2: 48 | R2: Appl Intell | V2: en | W2: DOI.org (Crossref)
A3: W3X5ABDE | B3: bookSection | C3: 2018 | D3: Swacha, Jakub | E3: SIPE: A Domain-Specific Language for Specifying Interactive Programming Exercises | F3: Towards a Synergistic Combination of Research and Practice in Software Engineering | G3: 978-3-319-65207-8 978-3-319-65208-5 | J3: http://link.springer.com/10.1007/978-3-319-65208-5_2 | K3: 2018 | L3: 44887.364 | M3: 44887.364 | N3: 44886.598 | O3: 15-29 | Q3: 733 | S3: SIPE | T3: Springer International Publishing | U3: Cham | W3: DOI.org (Crossref) | X3: Series Title: Studies in Computational Intelligence DOI: 10.1007/978-3-319-65208-5_2 | Y3: Kosiuczenko, Piotr; Madeyski, Lech
A4: 6BTFNFLU | B4: journalArticle | C4: 2018 | D4: Yang, Bin; Qiao, Lihong; Cai, Na; Zhu, Zuowei; Wulan, Muqi | E4: Manufacturing process information modeling using a metamodeling approach | F4: The International Journal of Advanced Manufacturing Technology | H4: 0268-3768, 1433-3015 | I4: 10.1007/s00170-016-9979-0 | J4: http://link.springer.com/10.1007/s00170-016-9979-0 | K4: 2018-02 | L4: 44887.364 | M4: 44887.364 | N4: 44886.598 | O4: 1579-1596 | P4: 5-8 | Q4: 94 | R4: Int J Adv Manuf Technol | V4: en | W4: DOI.org (Crossref)
A5: 7VKPKRGN | B5: bookSection | C5: 2010 | D5: Schlegel, Christian; Steck, Andreas; Brugali, Davide; Knoll, Alois | E5: Design Abstraction and Processes in Robotics: From Code-Driven to Model-Driven Engineering | F5: Simulation, Modeling, and Programming for Autonomous Robots | G5: 978-3-642-17318-9 978-3-642-17319-6 | J5: http://link.springer.com/10.1007/978-3-642-17319-6_31 | K5: 2010 | L5: 44887.364 | M5: 44887.364 | N5: 44886.598 | O5: 324-335 | Q5: 6472 | S5: Design Abstraction and Processes in Robotics | T5: Springer Berlin Heidelberg | U5: Berlin, Heidelberg | W5: DOI.org (Crossref) | X5: Series Title: Lecture Notes in Computer Science DOI: 10.1007/978-3-642-17319-6_31 | Y5: Ando, Noriaki; Balakirsky, Stephen; Hemker, Thomas; Reggiani, Monica; von Stryk, Oskar
A6: Q42UQ55J | B6: journalArticle | C6: 2019 | D6: Chen, Liming; Wang, Hu; Ye, Fan; Hu, Wei | E6: Comparative study of HDMRs and other popular metamodeling techniques for high dimensional problems | F6: Structural and Multidisciplinary Optimization | H6: 1615-147X, 1615-1488 | I6: 10.1007/s00158-018-2046-8 | J6: http://link.springer.com/10.1007/s00158-018-2046-8 | K6: 2019-01 | L6: 44887.364 | M6: 44887.364 | N6: 44886.598 | O6: 21-42 | P6: 1 | Q6: 59 | R6: Struct Multidisc Optim | V6: en | W6: DOI.org (Crossref)
A7: ZYBDV3MN | B7: journalArticle | C7: 2022 | D7: Di Ruscio, Davide; Kolovos, Dimitris; de Lara, Juan; Pierantonio, Alfonso; Tisi, Massimo; Wimmer, Manuel | E7: Low-code development and model-driven engineering: Two sides of the same coin? | F7: Software and Systems Modeling | H7: 1619-1366, 1619-1374 | I7: 10.1007/s10270-021-00970-2 | J7: https://link.springer.com/10.1007/s10270-021-00970-2 | K7: 2022-04 | L7: 44887.364 | M7: 44887.364 | N7: 44886.598 | O7: 437-446 | P7: 2 | Q7: 21 | R7: Softw Syst Model | S7: Low-code development and model-driven engineering | V7: en | W7: DOI.org (Crossref)
A8: 72LMJHKT | B8: bookSection | C8: 2016 | D8: Dingel, Juergen | E8: Complexity is the Only Constant: Trends in Computing and Their Relevance to Model Driven Engineering | F8: Graph Transformation | G8: 978-3-319-40529-2 978-3-319-40530-8 | J8: http://link.springer.com/10.1007/978-3-319-40530-8_1 | K8: 2016 | L8: 44887.364 | M8: 44887.364 | N8: 44886.598 | O8: 3-18 | Q8: 9761 | S8: Complexity is the Only Constant | T8: Springer International Publishing | U8: Cham | W8: DOI.org (Crossref) | X8: Series Title: Lecture Notes in Computer Science DOI: 10.1007/978-3-319-40530-8_1 | Y8: Echahed, Rachid; Minas, Mark
A9: JNMMFHBV | B9: journalArticle | C9: 2008 | D9: Hu, Wang; Enying, Li; Li, G. Y.; Zhong, Z. H. | E9: Optimization of sheet metal forming processes by the use of space mapping based metamodeling method | F9: The International Journal of Advanced Manufacturing Technology | H9: 0268-3768, 1433-3015 | I9: 10.1007/s00170-007-1253-z | J9: http://link.springer.com/10.1007/s00170-007-1253-z | K9: 2008-11 | L9: 44887.364 | M9: 44887.364 | N9: 44886.598 | O9: 642-655 | P9: 7-8 | Q9: 39 | R9: Int J Adv Manuf Technol | V9: en | W9: DOI.org (Crossref)
A10: NUQXM7FE | B10: journalArticle | C10: 2019 | D10: Coelho, Luis Pedro; Alves, Renato; Monteiro, Paulo; Huerta-Cepas, Jaime; Freitas, Ana Teresa; Bork, Peer | E10: NG-meta-profiler: fast processing of metagenomes using NGLess, a domain-specific language | F10: Microbiome | H10: 2049-2618 | I10: 10.1186/s40168-019-0684-8 | J10: https://microbiomejournal.biomedcentral.com/articles/10.1186/s40168-019-0684-8 | K10: 2019-12 | L10: 44887.364 | M10: 44887.364 | N10: 44886.598 | O10: 84 | P10: 1 | Q10: 7 | R10: Microbiome | S10: NG-meta-profiler | V10: en | W10: DOI.org (Crossref)
A11: JNNBIKDB | B11: bookSection | C11: 2003 | D11: Wu, Wenming; Dong, Yisheng | E11: Metamodeling-Based Semantic Web Languages | F11: E-Commerce and Web Technologies | G11: 978-3-540-40808-6 978-3-540-45229-4 | J11: http://link.springer.com/10.1007/978-3-540-45229-4_33 | K11: 2003 | L11: 44887.364 | M11: 44887.364 | N11: 44886.598 | O11: 339-347 | Q11: 2738 | T11: Springer Berlin Heidelberg | U11: Berlin, Heidelberg | W11: DOI.org (Crossref) | X11: Series Title: Lecture Notes in Computer Science DOI: 10.1007/978-3-540-45229-4_33 | Y11: Bauknecht, Kurt; Tjoa, A Min; Quirchmayr, Gerald | Z11: Goos, Gerhard; Hartmanis, Juris; van Leeuwen, Jan
A12: A89323UM | B12: bookSection | C12: 2010 | D12: Abramov, Jenny; Sturm, Arnon | E12: Supporting Layered Architecture Specifications: A Domain Modeling Approach | F12: Enterprise, Business-Process and Information Systems Modeling | G12: 978-3-642-13050-2 978-3-642-13051-9 | J12: http://link.springer.com/10.1007/978-3-642-13051-9_17 | K12: 2010 | L12: 44887.364 | M12: 44887.364 | N12: 44886.598 | O12: 195-207 | Q12: 50 | S12: Supporting Layered Architecture Specifications | T12: Springer Berlin Heidelberg | U12: Berlin, Heidelberg | V12: en | W12: DOI.org (Crossref) | X12: Series Title: Lecture Notes in Business Information Processing DOI: 10.1007/978-3-642-13051-9_17 | Y12: Bider, Ilia; Halpin, Terry; Krogstie, John; Nurcan, Selmin; Proper, Erik; Schmidt, Rainer; Ukor, Roland | Z12: van der Aalst, Will; Mylopoulos, John; Sadeh, Norman M.; Shaw, Michael J.; Szyperski, Clemens
A13: W5698GQL | B13: bookSection | C13: 2013 | D13: Grossmann, Georg; Jordan, Andreas; Muruganandha, Rishi; Selway, Matt; Stumptner, Markus | E13: Enabling Information Interoperability through Multi-domain Modeling | F13: Practice-Driven Research on Enterprise Transformation | G13: 978-3-642-38773-9 978-3-642-38774-6 | J13: http://link.springer.com/10.1007/978-3-642-38774-6_2 | K13: 2013 | L13: 44887.364 | M13: 44887.364 | N13: 44886.598 | O13: 16-33 | Q13: 151 | T13: Springer Berlin Heidelberg | U13: Berlin, Heidelberg | V13: en | W13: DOI.org (Crossref) | X13: Series Title: Lecture Notes in Business Information Processing DOI: 10.1007/978-3-642-38774-6_2 | Y13: Harmsen, Frank; Proper, Henderik A. | Z13: van der Aalst, Wil; Mylopoulos, John; Rosemann, Michael; Shaw, Michael J.; Szyperski, Clemens
A14: 6D2F4NLY | B14: journalArticle | C14: 2013 | D14: Mulo, Emmanuel; Zdun, Uwe; Dustdar, Schahram | E14: Domain-specific language for event-based compliance monitoring in process-driven SOAs | F14: Service Oriented Computing and Applications | H14: 1863-2386, 1863-2394 | I14: 10.1007/s11761-012-0121-3 | J14: http://link.springer.com/10.1007/s11761-012-0121-3 | K14: 2013-03 | L14: 44887.364 | M14: 44887.364 | N14: 44886.598 | O14: 59-73 | P14: 1 | Q14: 7 | R14: SOCA | V14: en | W14: DOI.org (Crossref)
A15: UQ2VR6UN | B15: bookSection | C15: 1991 | D15: van Gigch, John P. | E15: Diagnosis and Metamodeling of System Failures | F15: System Design Modeling and Metamodeling | G15: 978-1-4899-0678-6 978-1-4899-0676-2 | J15: http://link.springer.com/10.1007/978-1-4899-0676-2_14 | K15: 1991 | L15: 44887.364 | M15: 44887.364 | N15: 44886.598 | O15: 297-310 | T15: Springer US | U15: Boston, MA | V15: en | W15: DOI.org (Crossref) | X15: DOI: 10.1007/978-1-4899-0676-2_14
A16: UHWHUK72 | B16: journalArticle | C16: 2022 | D16: Kushari, Subrata; Gupta, Kritesh Kumar; Vaishali; Dey, Sudip | E16: Metamodeling-assisted probabilistic first ply failure analysis of laminated composite plates—RS-HDMR- and GPR-based approach | F16: Journal of the Brazilian Society of Mechanical Sciences and Engineering | H16: 1678-5878, 1806-3691 | I16: 10.1007/s40430-022-03674-w | J16: https://link.springer.com/10.1007/s40430-022-03674-w | K16: 2022-08 | L16: 44887.364 | M16: 44887.364 | N16: 44886.598 | O16: 374 | P16: 8 | Q16: 44 | R16: J Braz. Soc. Mech. Sci. Eng. | V16: en | W16: DOI.org (Crossref)
A17: PYVP2CUA | B17: bookSection | C17: 2011 | D17: Saleem, Muhammad Qaiser; Jaafar, Jafreezal; Hassan, Mohd Fadzil | E17: Security Modeling of SOA System Using Security Intent DSL | F17: Software Engineering and Computer Systems | G17: 978-3-642-22202-3 978-3-642-22203-0 | J17: http://link.springer.com/10.1007/978-3-642-22203-0_16 | K17: 2011 | L17: 44887.364 | M17: 44887.364 | N17: 44886.598 | O17: 176-190 | Q17: 181 | T17: Springer Berlin Heidelberg | U17: Berlin, Heidelberg | W17: DOI.org (Crossref) | X17: Series Title: Communications in Computer and Information Science DOI: 10.1007/978-3-642-22203-0_16 | Y17: Zain, Jasni Mohamad; Wan Mohd, Wan Maseri bt; El-Qawasmeh, Eyas
A18: R57L47XX | B18: bookSection | C18: 2019 | D18: Fickenscher, Jörg; Hannig, Frank; Teich, Jürgen | E18: DSL-Based Acceleration of Automotive Environment Perception and Mapping Algorithms for Embedded CPUs, GPUs, and FPGAs | F18: Architecture of Computing Systems – ARCS 2019 | G18: 978-3-030-18655-5 978-3-030-18656-2 | J18: http://link.springer.com/10.1007/978-3-030-18656-2_6 | K18: 2019 | L18: 44887.364 | M18: 44887.364 | N18: 44886.598 | O18: 71-86 | Q18: 11479 | T18: Springer International Publishing | U18: Cham | V18: en | W18: DOI.org (Crossref) | X18: Series Title: Lecture Notes in Computer Science DOI: 10.1007/978-3-030-18656-2_6 | Y18: Schoeberl, Martin; Hochberger, Christian; Uhrig, Sascha; Brehm, Jürgen; Pionteck, Thilo
A19: SGYHCIG2 | B19: journalArticle | C19: 2020 | D19: Iung, Aníbal; Carbonell, João; Marchezan, Luciano; Rodrigues, Elder; Bernardino, Maicon; Basso, Fabio Paulo; Medeiros, Bruno | E19: Systematic mapping study on domain-specific language development tools | F19: Empirical Software Engineering | H19: 1382-3256, 1573-7616 | I19: 10.1007/s10664-020-09872-1 | J19: https://link.springer.com/10.1007/s10664-020-09872-1 | K19: 2020-09 | L19: 44887.364 | M19: 44887.364 | N19: 44886.598 | O19: 4205-4249 | P19: 5 | Q19: 25 | R19: Empir Software Eng | V19: en | W19: DOI.org (Crossref)
A20: UVS2JJGV | B20: journalArticle | C20: 2022 | D20: Hoffmann, Benjamin; Urquhart, Neil; Chalmers, Kevin; Guckert, Michael | E20: An empirical evaluation of a novel domain-specific language – modelling vehicle routing problems with Athos | F20: Empirical Software Engineering | H20: 1382-3256, 1573-7616 | I20: 10.1007/s10664-022-10210-w | J20: https://link.springer.com/10.1007/s10664-022-10210-w | K20: 2022-12 | L20: 44887.364 | M20: 44887.364 | N20: 44886.598 | O20: 180 | P20: 7 | Q20: 27 | R20: Empir Software Eng | V20: en | W20: DOI.org (Crossref)
A21: VB46JCXX | B21: bookSection | C21: 2006 | D21: Sottet, Jean-Sébastien; Calvary, Gaëlle; Favre, Jean-Marie; Coutaz, Joëlle; Demeure, Alexandre; Balme, Lionel | E21: Towards Model Driven Engineering of Plastic User Interfaces | F21: Satellite Events at the MoDELS 2005 Conference | G21: 978-3-540-31780-7 978-3-540-31781-4 | J21: http://link.springer.com/10.1007/11663430_20 | K21: 2006 | L21: 44887.364 | M21: 44887.364 | N21: 44886.598 | O21: 191-200 | Q21: 3844 | T21: Springer Berlin Heidelberg | U21: Berlin, Heidelberg | W21: DOI.org (Crossref) | X21: Series Title: Lecture Notes in Computer Science DOI: 10.1007/11663430_20 | Y21: Bruel, Jean-Michel | Z21: Hutchison, David; Kanade, Takeo; Kittler, Josef; Kleinberg, Jon M.; Mattern, Friedemann; Mitchell, John C.; Naor, Moni; Nierstrasz, Oscar; Pandu Rangan, C.; Steffen, Bernhard; Sudan, Madhu; Terzopoulos, Demetri; Tygar, Dough; Vardi, Moshe Y.; Weikum, Gerhard
A22: AQ93UTSA | B22: journalArticle | C22: 2018 | D22: Chen, Liming; Qiu, Haobo; Jiang, Chen; Xiao, Mi; Gao, Liang | E22: Support Vector enhanced Kriging for metamodeling with noisy data | F22: Structural and Multidisciplinary Optimization | H22: 1615-147X, 1615-1488 | I22: 10.1007/s00158-017-1831-0 | J22: http://link.springer.com/10.1007/s00158-017-1831-0 | K22: 2018-04 | L22: 44887.364 | M22: 44887.364 | N22: 44886.598 | O22: 1611-1623 | P22: 4 | Q22: 57 | R22: Struct Multidisc Optim | V22: en | W22: DOI.org (Crossref)
A23: ID7RRDT3 | B23: bookSection | C23: 2008 | D23: Karagiannis, Dimitris; Höfferer, Peter | E23: Metamodeling as an Integration Concept | F23: Software and Data Technologies | G23: 978-3-540-70619-9 978-3-540-70621-2 | J23: http://link.springer.com/10.1007/978-3-540-70621-2_4 | K23: 2008 | L23: 44887.364 | M23: 44887.364 | N23: 44886.598 | O23: 37-50 | Q23: 10 | T23: Springer Berlin Heidelberg | U23: Berlin, Heidelberg | V23: en | W23: DOI.org (Crossref) | X23: ISSN: 1865-0929, 1865-0937 Series Title: Communications in Computer and Information Science DOI: 10.1007/978-3-540-70621-2_4 | Y23: Filipe, Joaquim; Shishkov, Boris; Helfert, Markus
A24: EYFZC2SV | B24: bookSection | C24: 2003 | D24: Hammond, Kevin; Michaelson, Greg | E24: Hume: A Domain-Specific Language for Real-Time Embedded Systems | F24: Generative Programming and Component Engineering | G24: 978-3-540-20102-1 978-3-540-39815-8 | J24: http://link.springer.com/10.1007/978-3-540-39815-8_3 | K24: 2003 | L24: 44887.364 | M24: 44887.364 | N24: 44886.598 | O24: 37-56 | Q24: 2830 | S24: Hume | T24: Springer Berlin Heidelberg | U24: Berlin, Heidelberg | W24: DOI.org (Crossref) | X24: Series Title: Lecture Notes in Computer Science DOI: 10.1007/978-3-540-39815-8_3 | Y24: Pfenning, Frank; Smaragdakis, Yannis | Z24: Goos, Gerhard; Hartmanis, Juris; van Leeuwen, Jan
A25: KRQA9EYE | B25: bookSection | C25: 2012 | D25: Kossakowski, Grzegorz; Amin, Nada; Rompf, Tiark; Odersky, Martin | E25: JavaScript as an Embedded DSL | F25: ECOOP 2012 – Object-Oriented Programming | G25: 978-3-642-31056-0 978-3-642-31057-7 | J25: http://link.springer.com/10.1007/978-3-642-31057-7_19 | K25: 2012 | L25: 44887.364 | M25: 44887.364 | N25: 44886.598 | O25: 409-434 | Q25: 7313 | T25: Springer Berlin Heidelberg | U25: Berlin, Heidelberg | W25: DOI.org (Crossref) | X25: Series Title: Lecture Notes in Computer Science DOI: 10.1007/978-3-642-31057-7_19 | Y25: Noble, James | Z25: Hutchison, David; Kanade, Takeo; Kittler, Josef; Kleinberg, Jon M.; Mattern, Friedemann; Mitchell, John C.; Naor, Moni; Nierstrasz, Oscar; Pandu Rangan, C.; Steffen, Bernhard; Sudan, Madhu; Terzopoulos, Demetri; Tygar, Doug; Vardi, Moshe Y.; Weikum, Gerhard
A26: 2G5FLEFB | B26: journalArticle | C26: 2013 | D26: Groenewegen, Danny M.; Visser, Eelco | E26: Integration of data validation and user interface concerns in a DSL for web applications | F26: Software & Systems Modeling | H26: 1619-1366, 1619-1374 | I26: 10.1007/s10270-010-0173-9 | J26: http://link.springer.com/10.1007/s10270-010-0173-9 | K26: 2013-02 | L26: 44887.364 | M26: 44887.364 | N26: 44886.598 | O26: 35-52 | P26: 1 | Q26: 12 | R26: Softw Syst Model | V26: en | W26: DOI.org (Crossref)
A27: K4YLN5WI | B27: journalArticle | C27: 1994 | D27: Zhang, Zhi; Jewett, Don L. | E27: DSL and MUSIC Under model misspecification and noise-conditions | F27: Brain Topography | H27: 0896-0267, 1573-6792 | I27: 10.1007/BF01186773 | J27: http://link.springer.com/10.1007/BF01186773 | K27: 1994-12 | L27: 44887.364 | M27: 44887.364 | N27: 44886.598 | O27: 151-161 | P27: 2 | Q27: 7 | R27: Brain Topogr | V27: en | W27: DOI.org (Crossref)
A28: XKN8WT8E | B28: journalArticle | C28: 2020 | D28: Bargigli, Leonardo; Riccetti, Luca; Russo, Alberto; Gallegati, Mauro | E28: Network calibration and metamodeling of a financial accelerator agent based model | F28: Journal of Economic Interaction and Coordination | H28: 1860-711X, 1860-7128 | I28: 10.1007/s11403-018-0217-8 | J28: http://link.springer.com/10.1007/s11403-018-0217-8 | K28: 2020-04 | L28: 44887.364 | M28: 44887.364 | N28: 44886.598 | O28: 413-440 | P28: 2 | Q28: 15 | R28: J Econ Interact Coord | V28: en | W28: DOI.org (Crossref)
A29: W99X6BAS | B29: bookSection | C29: 2021 | D29: Otter, Martin | E29: Multi-domain Modeling and Simulation | F29: Encyclopedia of Systems and Control | G29: 978-3-030-44183-8 978-3-030-44184-5 | J29: https://link.springer.com/10.1007/978-3-030-44184-5_140 | K29: 2021 | L29: 44887.364 | M29: 44887.364 | N29: 44886.598 | O29: 1367-1379 | T29: Springer International Publishing | U29: Cham | V29: en | W29: DOI.org (Crossref) | X29: DOI: 10.1007/978-3-030-44184-5_140 | Y29: Baillieul, John; Samad, Tariq
A30: LM8B7RYV | B30: journalArticle | C30: 2018 | D30: Fernandez-Duarte, Karem Prunella; Olaya-Galán, Nury Nathalia; Salas-Cárdenas, Sandra Patricia; Lopez-Rozo, Jazmin; Gutierrez-Fernandez, Maria Fernanda | E30: Bifidobacterium adolescentis (DSM 20083) and Lactobacillus casei (Lafti L26-DSL): Probiotics Able to Block the In Vitro Adherence of Rotavirus in MA104 Cells | F30: Probiotics and Antimicrobial Proteins | H30: 1867-1306, 1867-1314 | I30: 10.1007/s12602-017-9277-7 | J30: http://link.springer.com/10.1007/s12602-017-9277-7 | K30: 2018-03 | L30: 44887.364 | M30: 44887.364 | N30: 44886.598 | O30: 56-63 | P30: 1 | Q30: 10 | R30: Probiotics & Antimicro. Prot. | S30: Bifidobacterium adolescentis (DSM 20083) and Lactobacillus casei (Lafti L26-DSL) | V30: en | W30: DOI.org (Crossref)
A31: BYFGLPEU | B31: journalArticle | C31: 2016 | D31: Amaral, Vasco; Mernik, Marjan | E31: Special issue on quality in model-driven engineering | F31: Software Quality Journal | H31: 0963-9314, 1573-1367 | I31: 10.1007/s11219-016-9327-5 | J31: http://link.springer.com/10.1007/s11219-016-9327-5 | K31: 2016-09 | L31: 44887.364 | M31: 44887.364 | N31: 44886.598 | O31: 597-599 | P31: 3 | Q31: 24 | R31: Software Qual J | V31: en | W31: DOI.org (Crossref)
A32: D5KCLPHS | B32: bookSection | C32: 2009 | D32: Toro, Carlos; Graña, Manuel; Posada, Jorge; Vaquero, Javier; Sanín, Cesar; Szczerbicki, Edward | E32: Domain Modeling Based on Engineering Standards | F32: Knowledge-Based and Intelligent Information and Engineering Systems | G32: 978-3-642-04594-3 978-3-642-04595-0 | J32: http://link.springer.com/10.1007/978-3-642-04595-0_12 | K32: 2009 | L32: 44887.364 | M32: 44887.364 | N32: 44886.598 | O32: 95-102 | Q32: 5711 | T32: Springer Berlin Heidelberg | U32: Berlin, Heidelberg | W32: DOI.org (Crossref) | X32: Series Title: Lecture Notes in Computer Science DOI: 10.1007/978-3-642-04595-0_12 | Y32: Velásquez, Juan D.; Ríos, Sebastián A.; Howlett, Robert J.; Jain, Lakhmi C.
A33: 3HLW2KTQ | B33: bookSection | C33: 2008 | D33: Morbach, J.; Theißen, M.; Marquardt, W. | E33: An Introduction to Application Domain Modeling | F33: Collaborative and Distributed Chemical Engineering. From Understanding to Substantial Design Process Support | G33: 978-3-540-70551-2 978-3-540-70552-9 | J33: http://link.springer.com/10.1007/978-3-540-70552-9_4 | K33: 2008 | L33: 44887.364 | M33: 44887.364 | N33: 44886.598 | O33: 83-92 | Q33: 4970 | T33: Springer Berlin Heidelberg | U33: Berlin, Heidelberg | V33: en | W33: DOI.org (Crossref) | X33: ISSN: 0302-9743, 1611-3349 Series Title: Lecture Notes in Computer Science DOI: 10.1007/978-3-540-70552-9_4 | Y33: Nagl, Manfred; Marquardt, Wolfgang
A34: 2R9W2CEC | B34: journalArticle | C34: 2016 | D34: Yang, Qian; Cai, Shu; Dong, Shaowei; Chen, Lulu; Chen, Jifei; Cai, Tianming | E34: Biodegradation of 3-methyldiphenylether (MDE) by Hydrogenophaga atypical strain QY7-2 and cloning of the methy-oxidation gene mdeABCD | F34: Scientific Reports | H34: 2045-2322 | I34: 10.1038/srep39270 | J34: http://www.nature.com/articles/srep39270 | K34: 2016-12 | L34: 44887.364 | M34: 44887.364 | N34: 44886.598 | O34: 39270 | P34: 1 | Q34: 6 | R34: Sci Rep | V34: en | W34: DOI.org (Crossref)
A35: 9YFCUB8K | B35: bookSection | C35: 2002 | D35: Zielenski, Julian; Aznarez, Isabel; Onay, Tuncer; Tzounzouris, John; Markiewicz, Danuta; Tsui, Lap-Chee | E35: CFTR Mutation Detection by Multiplex Heteroduplex (mHET) Analysis on MDE Gel | F35: Cystic Fibrosis Methods and Protocols | G35: 978-1-59259-187-9 | J35: http://link.springer.com/10.1385/1-59259-187-6:03 | K35: 2002-03-04 | L35: 44887.364 | M35: 44887.364 | N35: 44886.598 | O35: 03-20 | Q35: 70 | T35: Humana Press | U35: New Jersey | V35: en | W35: DOI.org (Crossref) | X35: DOI: 10.1385/1-59259-187-6:03 DOI: 10.1385/1-59259-187-6:03
A36: ZTIQ238S | B36: bookSection | C36: 2005 | D36: Steel, Jim; Jézéquel, Jean-Marc | E36: Model Typing for Improving Reuse in Model-Driven Engineering | F36: Model Driven Engineering Languages and Systems | G36: 978-3-540-29010-0 978-3-540-32057-9 | J36: http://link.springer.com/10.1007/11557432_7 | K36: 2005 | L36: 44887.364 | M36: 44887.364 | N36: 44886.598 | O36: 84-96 | Q36: 3713 | T36: Springer Berlin Heidelberg | U36: Berlin, Heidelberg | W36: DOI.org (Crossref) | X36: Series Title: Lecture Notes in Computer Science DOI: 10.1007/11557432_7 | Y36: Briand, Lionel; Williams, Clay | Z36: Hutchison, David; Kanade, Takeo; Kittler, Josef; Kleinberg, Jon M.; Mattern, Friedemann; Mitchell, John C.; Naor, Moni; Nierstrasz, Oscar; Pandu Rangan, C.; Steffen, Bernhard; Sudan, Madhu; Terzopoulos, Demetri; Tygar, Dough; Vardi, Moshe Y.; Weikum, Gerhard
A37: 3JUDNKK6 | B37: bookSection | C37: 2016 | D37: Rouquette, Nicolas F. | E37: Simplifying OMG MOF-Based Metamodeling | F37: Leveraging Applications of Formal Methods, Verification and Validation: Discussion, Dissemination, Applications | G37: 978-3-319-47168-6 978-3-319-47169-3 | J37: http://link.springer.com/10.1007/978-3-319-47169-3_8 | K37: 2016 | L37: 44887.364 | M37: 44887.364 | N37: 44886.598 | O37: 97-118 | Q37: 9953 | T37: Springer International Publishing | U37: Cham | W37: DOI.org (Crossref) | X37: Series Title: Lecture Notes in Computer Science DOI: 10.1007/978-3-319-47169-3_8 | Y37: Margaria, Tiziana; Steffen, Bernhard
A38: KY4RYNHG | B38: bookSection | C38: 2010 | D38: Farwick, Matthias; Agreiter, Berthold; White, Jules; Forster, Simon; Lanzanasto, Norbert; Breu, Ruth | E38: A Web-Based Collaborative Metamodeling Environment with Secure Remote Model Access | F38: Web Engineering | G38: 978-3-642-13910-9 978-3-642-13911-6 | J38: http://link.springer.com/10.1007/978-3-642-13911-6_19 | K38: 2010 | L38: 44887.364 | M38: 44887.364 | N38: 44886.598 | O38: 278-291 | Q38: 6189 | T38: Springer Berlin Heidelberg | U38: Berlin, Heidelberg | W38: DOI.org (Crossref) | X38: Series Title: Lecture Notes in Computer Science DOI: 10.1007/978-3-642-13911-6_19 | Y38: Benatallah, Boualem; Casati, Fabio; Kappel, Gerti; Rossi, Gustavo | Z38: Hutchison, David; Kanade, Takeo; Kittler, Josef; Kleinberg, Jon M.; Mattern, Friedemann; Mitchell, John C.; Naor, Moni; Nierstrasz, Oscar; Pandu Rangan, C.; Steffen, Bernhard; Sudan, Madhu; Terzopoulos, Demetri; Tygar, Doug; Vardi, Moshe Y.; Weikum, Gerhard
A39: 958KA64C | B39: bookSection | C39: 2020 | D39: Amaral de Sousa, Victor; Burnay, Corentin; Snoeck, Monique | E39: B-MERODE: A Model-Driven Engineering and Artifact-Centric Approach to Generate Blockchain-Based Information Systems | F39: Advanced Information Systems Engineering | G39: 978-3-030-49434-6 978-3-030-49435-3 | J39: http://link.springer.com/10.1007/978-3-030-49435-3_8 | K39: 2020 | L39: 44887.364 | M39: 44887.364 | N39: 44886.598 | O39: 117-133 | Q39: 12127 | S39: B-MERODE | T39: Springer International Publishing | U39: Cham | V39: en | W39: DOI.org (Crossref) | X39: Series Title: Lecture Notes in Computer Science DOI: 10.1007/978-3-030-49435-3_8 | Y39: Dustdar, Schahram; Yu, Eric; Salinesi, Camille; Rieu, Dominique; Pant, Vik
A40: RGCKL82B | B40: bookSection | C40: 2016 | D40: Aarab, Zineb; Saidi, Rajaa; Rahmani, Moulay Driss | E40: Context Modeling and Metamodeling: A State of the Art | F40: Proceedings of the Mediterranean Conference on Information & Communication Technologies 2015 | G40: 978-3-319-30296-6 978-3-319-30298-0 | J40: http://link.springer.com/10.1007/978-3-319-30298-0_30 | K40: 2016 | L40: 44887.364 | M40: 44887.364 | N40: 44886.598 | O40: 287-295 | Q40: 381 | S40: Context Modeling and Metamodeling | T40: Springer International Publishing | U40: Cham | W40: DOI.org (Crossref) | X40: Series Title: Lecture Notes in Electrical Engineering DOI: 10.1007/978-3-319-30298-0_30 | Y40: El Oualkadi, Ahmed; Choubani, Fethi; El Moussati, Ali
...

Sheet 4. Selection Based on Title
A1: Key | B1: Item Type | C1: Publication Year | D1: Author | E1: Title | F1: Publication Title | G1: ISBN | H1: ISSN | I1: DOI | J1: Url | K1: Abstract Note | L1: Date | M1: Date Added | N1: Date Modified | O1: Access Date | P1: Pages | Q1: Num Pages | R1: Issue | S1: Volume | T1: Series | U1: Publisher | V1: Place | W1: Extra
A2: NDD6WRD9 | B2: =VLOOKUP(Tabelle4[[#This Row],[Key]],'3. Unique Results'!A:X,2,FALSE) -> conferencePaper | C2: =VLOOKUP(Tabelle4[[#This Row],[Key]],'3. Unique Results'!A:X,3,FALSE) -> 2022 | D2: =VLOOKUP(Tabelle4[[#This Row],[Key]],'3. Unique Results'!A:X,4,FALSE) -> d'Aloisio, Giordano | E2: =VLOOKUP(Tabelle4[[#This Row],[Key]],'3. Unique Results'!A:X,5,FALSE) -> Quality-Driven Machine Learning-Based Data Science Pipeline Realization: A Software Engineering Approach | F2: =VLOOKUP(Tabelle4[[#This Row],[Key]],'3. Unique Results'!A:X,6,FALSE) -> Proceedings of the ACM/IEEE 44th International Conference on Software Engineering: Companion Proceedings | G2: =VLOOKUP(Tabelle4[[#This Row],[Key]],'3. Unique Results'!A:X,7,FALSE) -> 978-1-4503-9223-5 | H2: =VLOOKUP(Tabelle4[[#This Row],[Key]],'3. Unique Results'!A:X,8,FALSE) | I2: =VLOOKUP(Tabelle4[[#This Row],[Key]],'3. Unique Results'!A:X,9,FALSE) -> 10.1145/3510454.3517067 | J2: =VLOOKUP(Tabelle4[[#This Row],[Key]],'3. Unique Results'!A:X,10,FALSE) -> https://doi.org/10.1145/3510454.3517067 | K2: =VLOOKUP(Tabelle4[[#This Row],[Key]],'3. Unique Results'!A:X,11,FALSE) -> 2022 | L2: =VLOOKUP(Tabelle4[[#This Row],[Key]],'3. Unique Results'!A:X,12,FALSE) -> 44887.364 | M2: =VLOOKUP(Tabelle4[[#This Row],[Key]],'3. Unique Results'!A:X,13,FALSE) -> 44887.412 | N2: =VLOOKUP(Tabelle4[[#This Row],[Key]],'3. Unique Results'!A:X,14,FALSE) -> 0 | O2: =VLOOKUP(Tabelle4[[#This Row],[Key]],'3. Unique Results'!A:X,15,FALSE) -> 291–293 | P2: =VLOOKUP(Tabelle4[[#This Row],[Key]],'3. Unique Results'!A:X,16,FALSE) | Q2: =VLOOKUP(Tabelle4[[#This Row],[Key]],'3. Unique Results'!A:X,17,FALSE) | R2: =VLOOKUP(Tabelle4[[#This Row],[Key]],'3. Unique Results'!A:X,18,FALSE) | S2: =VLOOKUP(Tabelle4[[#This Row],[Key]],'3. Unique Results'!A:X,19,FALSE) | T2: =VLOOKUP(Tabelle4[[#This Row],[Key]],'3. Unique Results'!A:X,20,FALSE) -> Association for Computing Machinery | U2: =VLOOKUP(Tabelle4[[#This Row],[Key]],'3. Unique Results'!A:X,21,FALSE) -> New York, NY, USA | V2: =VLOOKUP(Tabelle4[[#This Row],[Key]],'3. Unique Results'!A:X,22,FALSE) | W2: =VLOOKUP(Tabelle4[[#This Row],[Key]],'3. Unique Results'!A:X,23,FALSE)
A3: HMQVEDXS | B3: =VLOOKUP(Tabelle4[[#This Row],[Key]],'3. Unique Results'!A:X,2,FALSE) -> conferencePaper | C3: =VLOOKUP(Tabelle4[[#This Row],[Key]],'3. Unique Results'!A:X,3,FALSE) -> 2017 | D3: =VLOOKUP(Tabelle4[[#This Row],[Key]],'3. Unique Results'!A:X,4,FALSE) -> Dethlefs, Nina; Hawick, Ken | E3: =VLOOKUP(Tabelle4[[#This Row],[Key]],'3. Unique Results'!A:X,5,FALSE) -> DEFIne: A Fluent Interface DSL for Deep Learning Applications | F3: =VLOOKUP(Tabelle4[[#This Row],[Key]],'3. Unique Results'!A:X,6,FALSE) -> Proceedings of the 2nd International Workshop on Real World Domain Specific Languages | G3: =VLOOKUP(Tabelle4[[#This Row],[Key]],'3. Unique Results'!A:X,7,FALSE) -> 978-1-4503-4845-4 | H3: =VLOOKUP(Tabelle4[[#This Row],[Key]],'3. Unique Results'!A:X,8,FALSE) | I3: =VLOOKUP(Tabelle4[[#This Row],[Key]],'3. Unique Results'!A:X,9,FALSE) -> 10.1145/3039895.3039898 | J3: =VLOOKUP(Tabelle4[[#This Row],[Key]],'3. Unique Results'!A:X,10,FALSE) -> https://doi.org/10.1145/3039895.3039898 | K3: =VLOOKUP(Tabelle4[[#This Row],[Key]],'3. Unique Results'!A:X,11,FALSE) -> 2017 | L3: =VLOOKUP(Tabelle4[[#This Row],[Key]],'3. Unique Results'!A:X,12,FALSE) -> 44887.364 | M3: =VLOOKUP(Tabelle4[[#This Row],[Key]],'3. Unique Results'!A:X,13,FALSE) -> 44887.411 | N3: =VLOOKUP(Tabelle4[[#This Row],[Key]],'3. Unique Results'!A:X,14,FALSE) -> 0 | O3: =VLOOKUP(Tabelle4[[#This Row],[Key]],'3. Unique Results'!A:X,15,FALSE) | P3: =VLOOKUP(Tabelle4[[#This Row],[Key]],'3. Unique Results'!A:X,16,FALSE) | Q3: =VLOOKUP(Tabelle4[[#This Row],[Key]],'3. Unique Results'!A:X,17,FALSE) | R3: =VLOOKUP(Tabelle4[[#This Row],[Key]],'3. Unique Results'!A:X,18,FALSE) | S3: =VLOOKUP(Tabelle4[[#This Row],[Key]],'3. Unique Results'!A:X,19,FALSE) | T3: =VLOOKUP(Tabelle4[[#This Row],[Key]],'3. Unique Results'!A:X,20,FALSE) -> Association for Computing Machinery | U3: =VLOOKUP(Tabelle4[[#This Row],[Key]],'3. Unique Results'!A:X,21,FALSE) -> New York, NY, USA | V3: =VLOOKUP(Tabelle4[[#This Row],[Key]],'3. Unique Results'!A:X,22,FALSE) | W3: =VLOOKUP(Tabelle4[[#This Row],[Key]],'3. Unique Results'!A:X,23,FALSE)
A4: E77DCQEB | B4: =VLOOKUP(Tabelle4[[#This Row],[Key]],'3. Unique Results'!A:X,2,FALSE) -> conferencePaper | C4: =VLOOKUP(Tabelle4[[#This Row],[Key]],'3. Unique Results'!A:X,3,FALSE) -> 2021 | D4: =VLOOKUP(Tabelle4[[#This Row],[Key]],'3. Unique Results'!A:X,4,FALSE) -> Ries, Benoît; Guelfi, Nicolas; Jahic, Benjamin | E4: =VLOOKUP(Tabelle4[[#This Row],[Key]],'3. Unique Results'!A:X,5,FALSE) -> An MDE Method for Improving Deep Learning Dataset Requirements Engineering using Alloy and UML | F4: =VLOOKUP(Tabelle4[[#This Row],[Key]],'3. Unique Results'!A:X,6,FALSE) -> Proceedings of the 9th International Conference on Model-Driven Engineering and Software Development, MODELSWARD 2021, Online Streaming, February 8-10, 2021 | G4: =VLOOKUP(Tabelle4[[#This Row],[Key]],'3. Unique Results'!A:X,7,FALSE) | H4: =VLOOKUP(Tabelle4[[#This Row],[Key]],'3. Unique Results'!A:X,8,FALSE) | I4: =VLOOKUP(Tabelle4[[#This Row],[Key]],'3. Unique Results'!A:X,9,FALSE) -> 10.5220/0010216600410052 | J4: =VLOOKUP(Tabelle4[[#This Row],[Key]],'3. Unique Results'!A:X,10,FALSE) -> https://doi.org/10.5220/0010216600410052 | K4: =VLOOKUP(Tabelle4[[#This Row],[Key]],'3. Unique Results'!A:X,11,FALSE) -> 2021 | L4: =VLOOKUP(Tabelle4[[#This Row],[Key]],'3. Unique Results'!A:X,12,FALSE) -> 44887.364 | M4: =VLOOKUP(Tabelle4[[#This Row],[Key]],'3. Unique Results'!A:X,13,FALSE) -> 44887.364 | N4: =VLOOKUP(Tabelle4[[#This Row],[Key]],'3. Unique Results'!A:X,14,FALSE) -> 0 | O4: =VLOOKUP(Tabelle4[[#This Row],[Key]],'3. Unique Results'!A:X,15,FALSE) -> 41–52 | P4: =VLOOKUP(Tabelle4[[#This Row],[Key]],'3. Unique Results'!A:X,16,FALSE) | Q4: =VLOOKUP(Tabelle4[[#This Row],[Key]],'3. Unique Results'!A:X,17,FALSE) | R4: =VLOOKUP(Tabelle4[[#This Row],[Key]],'3. Unique Results'!A:X,18,FALSE) | S4: =VLOOKUP(Tabelle4[[#This Row],[Key]],'3. Unique Results'!A:X,19,FALSE) | T4: =VLOOKUP(Tabelle4[[#This Row],[Key]],'3. Unique Results'!A:X,20,FALSE) -> SCITEPRESS | U4: =VLOOKUP(Tabelle4[[#This Row],[Key]],'3. Unique Results'!A:X,21,FALSE) | V4: =VLOOKUP(Tabelle4[[#This Row],[Key]],'3. Unique Results'!A:X,22,FALSE) | W4: =VLOOKUP(Tabelle4[[#This Row],[Key]],'3. Unique Results'!A:X,23,FALSE)
A5: 9FSARRET | B5: =VLOOKUP(Tabelle4[[#This Row],[Key]],'3. Unique Results'!A:X,2,FALSE) -> book | C5: =VLOOKUP(Tabelle4[[#This Row],[Key]],'3. Unique Results'!A:X,3,FALSE) -> 2009 | D5: =VLOOKUP(Tabelle4[[#This Row],[Key]],'3. Unique Results'!A:X,4,FALSE) -> Calleja, A.; Pace, G. J. | E5: =VLOOKUP(Tabelle4[[#This Row],[Key]],'3. Unique Results'!A:X,5,FALSE) -> A domain-specific embedded language approach for the scripting of game artificial intelligence | F5: =VLOOKUP(Tabelle4[[#This Row],[Key]],'3. Unique Results'!A:X,6,FALSE) | G5: =VLOOKUP(Tabelle4[[#This Row],[Key]],'3. Unique Results'!A:X,7,FALSE) | H5: =VLOOKUP(Tabelle4[[#This Row],[Key]],'3. Unique Results'!A:X,8,FALSE) | I5: =VLOOKUP(Tabelle4[[#This Row],[Key]],'3. Unique Results'!A:X,9,FALSE) | J5: =VLOOKUP(Tabelle4[[#This Row],[Key]],'3. Unique Results'!A:X,10,FALSE) -> https://www.um.edu.mt/library/oar/handle/123456789/27604 | K5: =VLOOKUP(Tabelle4[[#This Row],[Key]],'3. Unique Results'!A:X,11,FALSE) -> 2009 | L5: =VLOOKUP(Tabelle4[[#This Row],[Key]],'3. Unique Results'!A:X,12,FALSE) -> 44887.364 | M5: =VLOOKUP(Tabelle4[[#This Row],[Key]],'3. Unique Results'!A:X,13,FALSE) -> 44887.364 | N5: =VLOOKUP(Tabelle4[[#This Row],[Key]],'3. Unique Results'!A:X,14,FALSE) -> 0 | O5: =VLOOKUP(Tabelle4[[#This Row],[Key]],'3. Unique Results'!A:X,15,FALSE) | P5: =VLOOKUP(Tabelle4[[#This Row],[Key]],'3. Unique Results'!A:X,16,FALSE) | Q5: =VLOOKUP(Tabelle4[[#This Row],[Key]],'3. Unique Results'!A:X,17,FALSE) | R5: =VLOOKUP(Tabelle4[[#This Row],[Key]],'3. Unique Results'!A:X,18,FALSE) | S5: =VLOOKUP(Tabelle4[[#This Row],[Key]],'3. Unique Results'!A:X,19,FALSE) | T5: =VLOOKUP(Tabelle4[[#This Row],[Key]],'3. Unique Results'!A:X,20,FALSE) -> um.edu.mt | U5: =VLOOKUP(Tabelle4[[#This Row],[Key]],'3. Unique Results'!A:X,21,FALSE) | V5: =VLOOKUP(Tabelle4[[#This Row],[Key]],'3. Unique Results'!A:X,22,FALSE) | W5: =VLOOKUP(Tabelle4[[#This Row],[Key]],'3. Unique Results'!A:X,23,FALSE)
A6: DFHPWT8X | B6: =VLOOKUP(Tabelle4[[#This Row],[Key]],'3. Unique Results'!A:X,2,FALSE) -> journalArticle | C6: =VLOOKUP(Tabelle4[[#This Row],[Key]],'3. Unique Results'!A:X,3,FALSE) -> 2018 | D6: =VLOOKUP(Tabelle4[[#This Row],[Key]],'3. Unique Results'!A:X,4,FALSE) -> Ghiasi, Ramin; Ghasemi, Mohammad Reza; Noori, Mohammad N. | E6: =VLOOKUP(Tabelle4[[#This Row],[Key]],'3. Unique Results'!A:X,5,FALSE) -> Comparative studies of metamodeling and AI-Based techniques in damage detection of structures | F6: =VLOOKUP(Tabelle4[[#This Row],[Key]],'3. Unique Results'!A:X,6,FALSE) -> Adv. Eng. Softw. | G6: =VLOOKUP(Tabelle4[[#This Row],[Key]],'3. Unique Results'!A:X,7,FALSE) | H6: =VLOOKUP(Tabelle4[[#This Row],[Key]],'3. Unique Results'!A:X,8,FALSE) | I6: =VLOOKUP(Tabelle4[[#This Row],[Key]],'3. Unique Results'!A:X,9,FALSE) -> 10.1016/j.advengsoft.2018.02.006 | J6: =VLOOKUP(Tabelle4[[#This Row],[Key]],'3. Unique Results'!A:X,10,FALSE) -> https://doi.org/10.1016/j.advengsoft.2018.02.006 | K6: =VLOOKUP(Tabelle4[[#This Row],[Key]],'3. Unique Results'!A:X,11,FALSE) -> 2018 | L6: =VLOOKUP(Tabelle4[[#This Row],[Key]],'3. Unique Results'!A:X,12,FALSE) -> 44887.364 | M6: =VLOOKUP(Tabelle4[[#This Row],[Key]],'3. Unique Results'!A:X,13,FALSE) -> 44887.364 | N6: =VLOOKUP(Tabelle4[[#This Row],[Key]],'3. Unique Results'!A:X,14,FALSE) -> 0 | O6: =VLOOKUP(Tabelle4[[#This Row],[Key]],'3. Unique Results'!A:X,15,FALSE) -> 101–112 | P6: =VLOOKUP(Tabelle4[[#This Row],[Key]],'3. Unique Results'!A:X,16,FALSE) | Q6: =VLOOKUP(Tabelle4[[#This Row],[Key]],'3. Unique Results'!A:X,17,FALSE) -> 125 | R6: =VLOOKUP(Tabelle4[[#This Row],[Key]],'3. Unique Results'!A:X,18,FALSE) | S6: =VLOOKUP(Tabelle4[[#This Row],[Key]],'3. Unique Results'!A:X,19,FALSE) | T6: =VLOOKUP(Tabelle4[[#This Row],[Key]],'3. Unique Results'!A:X,20,FALSE) | U6: =VLOOKUP(Tabelle4[[#This Row],[Key]],'3. Unique Results'!A:X,21,FALSE) | V6: =VLOOKUP(Tabelle4[[#This Row],[Key]],'3. Unique Results'!A:X,22,FALSE) | W6: =VLOOKUP(Tabelle4[[#This Row],[Key]],'3. Unique Results'!A:X,23,FALSE)
A7: QGZZF9WA | B7: =VLOOKUP(Tabelle4[[#This Row],[Key]],'3. Unique Results'!A:X,2,FALSE) -> conferencePaper | C7: =VLOOKUP(Tabelle4[[#This Row],[Key]],'3. Unique Results'!A:X,3,FALSE) -> 2017 | D7: =VLOOKUP(Tabelle4[[#This Row],[Key]],'3. Unique Results'!A:X,4,FALSE) -> Zhao, Tian; Huang, Xiaobing; Cao, Yu | E7: =VLOOKUP(Tabelle4[[#This Row],[Key]],'3. Unique Results'!A:X,5,FALSE) -> DeepDSL: A Compilation-based Domain-Specific Language for Deep Learning | F7: =VLOOKUP(Tabelle4[[#This Row],[Key]],'3. Unique Results'!A:X,6,FALSE) -> 5th International Conference on Learning Representations, ICLR 2017, Toulon, France, April 24-26, 2017, Conference Track Proceedings | G7: =VLOOKUP(Tabelle4[[#This Row],[Key]],'3. Unique Results'!A:X,7,FALSE) | H7: =VLOOKUP(Tabelle4[[#This Row],[Key]],'3. Unique Results'!A:X,8,FALSE) | I7: =VLOOKUP(Tabelle4[[#This Row],[Key]],'3. Unique Results'!A:X,9,FALSE) | J7: =VLOOKUP(Tabelle4[[#This Row],[Key]],'3. Unique Results'!A:X,10,FALSE) -> https://openreview.net/forum?id=Bks8cPcxe | K7: =VLOOKUP(Tabelle4[[#This Row],[Key]],'3. Unique Results'!A:X,11,FALSE) -> 2017 | L7: =VLOOKUP(Tabelle4[[#This Row],[Key]],'3. Unique Results'!A:X,12,FALSE) -> 44887.364 | M7: =VLOOKUP(Tabelle4[[#This Row],[Key]],'3. Unique Results'!A:X,13,FALSE) -> 44887.364 | N7: =VLOOKUP(Tabelle4[[#This Row],[Key]],'3. Unique Results'!A:X,14,FALSE) -> 0 | O7: =VLOOKUP(Tabelle4[[#This Row],[Key]],'3. Unique Results'!A:X,15,FALSE) | P7: =VLOOKUP(Tabelle4[[#This Row],[Key]],'3. Unique Results'!A:X,16,FALSE) | Q7: =VLOOKUP(Tabelle4[[#This Row],[Key]],'3. Unique Results'!A:X,17,FALSE) | R7: =VLOOKUP(Tabelle4[[#This Row],[Key]],'3. Unique Results'!A:X,18,FALSE) | S7: =VLOOKUP(Tabelle4[[#This Row],[Key]],'3. Unique Results'!A:X,19,FALSE) | T7: =VLOOKUP(Tabelle4[[#This Row],[Key]],'3. Unique Results'!A:X,20,FALSE) -> OpenReview.net | U7: =VLOOKUP(Tabelle4[[#This Row],[Key]],'3. Unique Results'!A:X,21,FALSE) | V7: =VLOOKUP(Tabelle4[[#This Row],[Key]],'3. Unique Results'!A:X,22,FALSE) | W7: =VLOOKUP(Tabelle4[[#This Row],[Key]],'3. Unique Results'!A:X,23,FALSE)
A8: YT9ZH6FN | B8: =VLOOKUP(Tabelle4[[#This Row],[Key]],'3. Unique Results'!A:X,2,FALSE) -> conferencePaper | C8: =VLOOKUP(Tabelle4[[#This Row],[Key]],'3. Unique Results'!A:X,3,FALSE) -> 2011 | D8: =VLOOKUP(Tabelle4[[#This Row],[Key]],'3. Unique Results'!A:X,4,FALSE) -> Chafi, Hassan; Sujeeth, Arvind K.; Brown, Kevin J.; Lee, HyoukJoong; Atreya, Anand R.; Olukotun, Kunle | E8: =VLOOKUP(Tabelle4[[#This Row],[Key]],'3. Unique Results'!A:X,5,FALSE) -> A Domain-Specific Approach to Heterogeneous Parallelism | F8: =VLOOKUP(Tabelle4[[#This Row],[Key]],'3. Unique Results'!A:X,6,FALSE) -> Proceedings of the 16th ACM Symposium on Principles and Practice of Parallel Programming | G8: =VLOOKUP(Tabelle4[[#This Row],[Key]],'3. Unique Results'!A:X,7,FALSE) -> 978-1-4503-0119-0 | H8: =VLOOKUP(Tabelle4[[#This Row],[Key]],'3. Unique Results'!A:X,8,FALSE) | I8: =VLOOKUP(Tabelle4[[#This Row],[Key]],'3. Unique Results'!A:X,9,FALSE) -> 10.1145/1941553.1941561 | J8: =VLOOKUP(Tabelle4[[#This Row],[Key]],'3. Unique Results'!A:X,10,FALSE) -> https://doi.org/10.1145/1941553.1941561 | K8: =VLOOKUP(Tabelle4[[#This Row],[Key]],'3. Unique Results'!A:X,11,FALSE) -> 2011 | L8: =VLOOKUP(Tabelle4[[#This Row],[Key]],'3. Unique Results'!A:X,12,FALSE) -> 44887.364 | M8: =VLOOKUP(Tabelle4[[#This Row],[Key]],'3. Unique Results'!A:X,13,FALSE) -> 44887.364 | N8: =VLOOKUP(Tabelle4[[#This Row],[Key]],'3. Unique Results'!A:X,14,FALSE) -> 0 | O8: =VLOOKUP(Tabelle4[[#This Row],[Key]],'3. Unique Results'!A:X,15,FALSE) -> 35–46 | P8: =VLOOKUP(Tabelle4[[#This Row],[Key]],'3. Unique Results'!A:X,16,FALSE) | Q8: =VLOOKUP(Tabelle4[[#This Row],[Key]],'3. Unique Results'!A:X,17,FALSE) | R8: =VLOOKUP(Tabelle4[[#This Row],[Key]],'3. Unique Results'!A:X,18,FALSE) | S8: =VLOOKUP(Tabelle4[[#This Row],[Key]],'3. Unique Results'!A:X,19,FALSE) | T8: =VLOOKUP(Tabelle4[[#This Row],[Key]],'3. Unique Results'!A:X,20,FALSE) -> Association for Computing Machinery | U8: =VLOOKUP(Tabelle4[[#This Row],[Key]],'3. Unique Results'!A:X,21,FALSE) -> New York, NY, USA | V8: =VLOOKUP(Tabelle4[[#This Row],[Key]],'3. Unique Results'!A:X,22,FALSE) | W8: =VLOOKUP(Tabelle4[[#This Row],[Key]],'3. Unique Results'!A:X,23,FALSE)
A9: E3RZ35LZ | B9: =VLOOKUP(Tabelle4[[#This Row],[Key]],'3. Unique Results'!A:X,2,FALSE) -> bookSection | C9: =VLOOKUP(Tabelle4[[#This Row],[Key]],'3. Unique Results'!A:X,3,FALSE) -> 2009 | D9: =VLOOKUP(Tabelle4[[#This Row],[Key]],'3. Unique Results'!A:X,4,FALSE) -> García-Díaz, Vicente; Tolosa, Jose Barranquero; G-Bustelo, B. Cristina Pelayo; Palacios-González, Elías; Sanjuan-Martínez, Óscar; Crespo, Rubén González | E9: =VLOOKUP(Tabelle4[[#This Row],[Key]],'3. Unique Results'!A:X,5,FALSE) -> TALISMAN MDE Framework: An Architecture for Intelligent Model-Driven Engineering | F9: =VLOOKUP(Tabelle4[[#This Row],[Key]],'3. Unique Results'!A:X,6,FALSE) -> Distributed Computing, Artificial Intelligence, Bioinformatics, Soft Computing, and Ambient Assisted Living | G9: =VLOOKUP(Tabelle4[[#This Row],[Key]],'3. Unique Results'!A:X,7,FALSE) -> 978-3-642-02480-1 978-3-642-02481-8 | H9: =VLOOKUP(Tabelle4[[#This Row],[Key]],'3. Unique Results'!A:X,8,FALSE) | I9: =VLOOKUP(Tabelle4[[#This Row],[Key]],'3. Unique Results'!A:X,9,FALSE) | J9: =VLOOKUP(Tabelle4[[#This Row],[Key]],'3. Unique Results'!A:X,10,FALSE) -> http://link.springer.com/10.1007/978-3-642-02481-8_43 | K9: =VLOOKUP(Tabelle4[[#This Row],[Key]],'3. Unique Results'!A:X,11,FALSE) -> 2009 | L9: =VLOOKUP(Tabelle4[[#This Row],[Key]],'3. Unique Results'!A:X,12,FALSE) -> 44887.364 | M9: =VLOOKUP(Tabelle4[[#This Row],[Key]],'3. Unique Results'!A:X,13,FALSE) -> 44887.364 | N9: =VLOOKUP(Tabelle4[[#This Row],[Key]],'3. Unique Results'!A:X,14,FALSE) -> 44886.598 | O9: =VLOOKUP(Tabelle4[[#This Row],[Key]],'3. Unique Results'!A:X,15,FALSE) -> 299-306 | P9: =VLOOKUP(Tabelle4[[#This Row],[Key]],'3. Unique Results'!A:X,16,FALSE) | Q9: =VLOOKUP(Tabelle4[[#This Row],[Key]],'3. Unique Results'!A:X,17,FALSE) -> 5518 | R9: =VLOOKUP(Tabelle4[[#This Row],[Key]],'3. Unique Results'!A:X,18,FALSE) | S9: =VLOOKUP(Tabelle4[[#This Row],[Key]],'3. Unique Results'!A:X,19,FALSE) -> TALISMAN MDE Framework | T9: =VLOOKUP(Tabelle4[[#This Row],[Key]],'3. Unique Results'!A:X,20,FALSE) -> Springer Berlin Heidelberg | U9: =VLOOKUP(Tabelle4[[#This Row],[Key]],'3. Unique Results'!A:X,21,FALSE) -> Berlin, Heidelberg | V9: =VLOOKUP(Tabelle4[[#This Row],[Key]],'3. Unique Results'!A:X,22,FALSE) | W9: =VLOOKUP(Tabelle4[[#This Row],[Key]],'3. Unique Results'!A:X,23,FALSE) -> DOI.org (Crossref)
A10: 8RC6BWB6 | B10: =VLOOKUP(Tabelle4[[#This Row],[Key]],'3. Unique Results'!A:X,2,FALSE) -> journalArticle | C10: =VLOOKUP(Tabelle4[[#This Row],[Key]],'3. Unique Results'!A:X,3,FALSE) -> 2020 | D10: =VLOOKUP(Tabelle4[[#This Row],[Key]],'3. Unique Results'!A:X,4,FALSE) -> Meacham, Sofia; Pech, Vaclav; Nauck, Detlef | E10: =VLOOKUP(Tabelle4[[#This Row],[Key]],'3. Unique Results'!A:X,5,FALSE) -> AdaptiveVLE: An Integrated Framework for Personalized Online Education Using MPS JetBrains Domain-Specific Modeling Environment | F10: =VLOOKUP(Tabelle4[[#This Row],[Key]],'3. Unique Results'!A:X,6,FALSE) -> IEEE Access | G10: =VLOOKUP(Tabelle4[[#This Row],[Key]],'3. Unique Results'!A:X,7,FALSE) | H10: =VLOOKUP(Tabelle4[[#This Row],[Key]],'3. Unique Results'!A:X,8,FALSE) | I10: =VLOOKUP(Tabelle4[[#This Row],[Key]],'3. Unique Results'!A:X,9,FALSE) -> 10.1109/ACCESS.2020.3029888 | J10: =VLOOKUP(Tabelle4[[#This Row],[Key]],'3. Unique Results'!A:X,10,FALSE) | K10: =VLOOKUP(Tabelle4[[#This Row],[Key]],'3. Unique Results'!A:X,11,FALSE) -> 2020 | L10: =VLOOKUP(Tabelle4[[#This Row],[Key]],'3. Unique Results'!A:X,12,FALSE) -> 44887.364 | M10: =VLOOKUP(Tabelle4[[#This Row],[Key]],'3. Unique Results'!A:X,13,FALSE) -> 44887.364 | N10: =VLOOKUP(Tabelle4[[#This Row],[Key]],'3. Unique Results'!A:X,14,FALSE) -> 0 | O10: =VLOOKUP(Tabelle4[[#This Row],[Key]],'3. Unique Results'!A:X,15,FALSE) -> 184621-184632 | P10: =VLOOKUP(Tabelle4[[#This Row],[Key]],'3. Unique Results'!A:X,16,FALSE) | Q10: =VLOOKUP(Tabelle4[[#This Row],[Key]],'3. Unique Results'!A:X,17,FALSE) -> 8 | R10: =VLOOKUP(Tabelle4[[#This Row],[Key]],'3. Unique Results'!A:X,18,FALSE) | S10: =VLOOKUP(Tabelle4[[#This Row],[Key]],'3. Unique Results'!A:X,19,FALSE) | T10: =VLOOKUP(Tabelle4[[#This Row],[Key]],'3. Unique Results'!A:X,20,FALSE) | U10: =VLOOKUP(Tabelle4[[#This Row],[Key]],'3. Unique Results'!A:X,21,FALSE) | V10: =VLOOKUP(Tabelle4[[#This Row],[Key]],'3. Unique Results'!A:X,22,FALSE) | W10: =VLOOKUP(Tabelle4[[#This Row],[Key]],'3. Unique Results'!A:X,23,FALSE)
A11: 4TJQZERC | B11: =VLOOKUP(Tabelle4[[#This Row],[Key]],'3. Unique Results'!A:X,2,FALSE) -> conferencePaper | C11: =VLOOKUP(Tabelle4[[#This Row],[Key]],'3. Unique Results'!A:X,3,FALSE) -> 2020 | D11: =VLOOKUP(Tabelle4[[#This Row],[Key]],'3. Unique Results'!A:X,4,FALSE) -> Ziaei, Mahdi; Zamani, Bahman; Bohlooli, Ali | E11: =VLOOKUP(Tabelle4[[#This Row],[Key]],'3. Unique Results'!A:X,5,FALSE) -> A Model-Driven Approach for IoT-Based Monitoring Systems in Industry 4.0 | F11: =VLOOKUP(Tabelle4[[#This Row],[Key]],'3. Unique Results'!A:X,6,FALSE) -> 2020 4th International Conference on Smart City, Internet of Things and Applications (SCIOT) | G11: =VLOOKUP(Tabelle4[[#This Row],[Key]],'3. Unique Results'!A:X,7,FALSE) | H11: =VLOOKUP(Tabelle4[[#This Row],[Key]],'3. Unique Results'!A:X,8,FALSE) | I11: =VLOOKUP(Tabelle4[[#This Row],[Key]],'3. Unique Results'!A:X,9,FALSE) -> 10.1109/SCIOT50840.2020.9250202 | J11: =VLOOKUP(Tabelle4[[#This Row],[Key]],'3. Unique Results'!A:X,10,FALSE) | K11: =VLOOKUP(Tabelle4[[#This Row],[Key]],'3. Unique Results'!A:X,11,FALSE) -> 2020 | L11: =VLOOKUP(Tabelle4[[#This Row],[Key]],'3. Unique Results'!A:X,12,FALSE) -> 44887.364 | M11: =VLOOKUP(Tabelle4[[#This Row],[Key]],'3. Unique Results'!A:X,13,FALSE) -> 44887.364 | N11: =VLOOKUP(Tabelle4[[#This Row],[Key]],'3. Unique Results'!A:X,14,FALSE) -> 0 | O11: =VLOOKUP(Tabelle4[[#This Row],[Key]],'3. Unique Results'!A:X,15,FALSE) -> 99-105 | P11: =VLOOKUP(Tabelle4[[#This Row],[Key]],'3. Unique Results'!A:X,16,FALSE) | Q11: =VLOOKUP(Tabelle4[[#This Row],[Key]],'3. Unique Results'!A:X,17,FALSE) | R11: =VLOOKUP(Tabelle4[[#This Row],[Key]],'3. Unique Results'!A:X,18,FALSE) | S11: =VLOOKUP(Tabelle4[[#This Row],[Key]],'3. Unique Results'!A:X,19,FALSE) | T11: =VLOOKUP(Tabelle4[[#This Row],[Key]],'3. Unique Results'!A:X,20,FALSE) | U11: =VLOOKUP(Tabelle4[[#This Row],[Key]],'3. Unique Results'!A:X,21,FALSE) | V11: =VLOOKUP(Tabelle4[[#This Row],[Key]],'3. Unique Results'!A:X,22,FALSE) | W11: =VLOOKUP(Tabelle4[[#This Row],[Key]],'3. Unique Results'!A:X,23,FALSE)
A12: AZ4AEJ6J | B12: =VLOOKUP(Tabelle4[[#This Row],[Key]],'3. Unique Results'!A:X,2,FALSE) -> conferencePaper | C12: =VLOOKUP(Tabelle4[[#This Row],[Key]],'3. Unique Results'!A:X,3,FALSE) -> 2019 | D12: =VLOOKUP(Tabelle4[[#This Row],[Key]],'3. Unique Results'!A:X,4,FALSE) -> Shokooh, Shervin; Nordvik, Geir | E12: =VLOOKUP(Tabelle4[[#This Row],[Key]],'3. Unique Results'!A:X,5,FALSE) -> A Model-Driven Approach for Situational Intelligence & Operational Awareness | F12: =VLOOKUP(Tabelle4[[#This Row],[Key]],'3. Unique Results'!A:X,6,FALSE) -> 2019 Petroleum and Chemical Industry Conference Europe (PCIC EUROPE) | G12: =VLOOKUP(Tabelle4[[#This Row],[Key]],'3. Unique Results'!A:X,7,FALSE) | H12: =VLOOKUP(Tabelle4[[#This Row],[Key]],'3. Unique Results'!A:X,8,FALSE) | I12: =VLOOKUP(Tabelle4[[#This Row],[Key]],'3. Unique Results'!A:X,9,FALSE) -> 10.23919/PCICEurope46863.2019.9011632 | J12: =VLOOKUP(Tabelle4[[#This Row],[Key]],'3. Unique Results'!A:X,10,FALSE) | K12: =VLOOKUP(Tabelle4[[#This Row],[Key]],'3. Unique Results'!A:X,11,FALSE) -> 2019 | L12: =VLOOKUP(Tabelle4[[#This Row],[Key]],'3. Unique Results'!A:X,12,FALSE) -> 44887.364 | M12: =VLOOKUP(Tabelle4[[#This Row],[Key]],'3. Unique Results'!A:X,13,FALSE) -> 44887.364 | N12: =VLOOKUP(Tabelle4[[#This Row],[Key]],'3. Unique Results'!A:X,14,FALSE) -> 0 | O12: =VLOOKUP(Tabelle4[[#This Row],[Key]],'3. Unique Results'!A:X,15,FALSE) -> 1-8 | P12: =VLOOKUP(Tabelle4[[#This Row],[Key]],'3. Unique Results'!A:X,16,FALSE) | Q12: =VLOOKUP(Tabelle4[[#This Row],[Key]],'3. Unique Results'!A:X,17,FALSE) | R12: =VLOOKUP(Tabelle4[[#This Row],[Key]],'3. Unique Results'!A:X,18,FALSE) | S12: =VLOOKUP(Tabelle4[[#This Row],[Key]],'3. Unique Results'!A:X,19,FALSE) | T12: =VLOOKUP(Tabelle4[[#This Row],[Key]],'3. Unique Results'!A:X,20,FALSE) | U12: =VLOOKUP(Tabelle4[[#This Row],[Key]],'3. Unique Results'!A:X,21,FALSE) | V12: =VLOOKUP(Tabelle4[[#This Row],[Key]],'3. Unique Results'!A:X,22,FALSE) | W12: =VLOOKUP(Tabelle4[[#This Row],[Key]],'3. Unique Results'!A:X,23,FALSE)
A13: DPT5MS8D | B13: =VLOOKUP(Tabelle4[[#This Row],[Key]],'3. Unique Results'!A:X,2,FALSE) -> conferencePaper | C13: =VLOOKUP(Tabelle4[[#This Row],[Key]],'3. Unique Results'!A:X,3,FALSE) -> 2021 | D13: =VLOOKUP(Tabelle4[[#This Row],[Key]],'3. Unique Results'!A:X,4,FALSE) -> Cong, Jason | E13: =VLOOKUP(Tabelle4[[#This Row],[Key]],'3. Unique Results'!A:X,5,FALSE) -> From Parallelization to Customization – Challenges and Opportunities | F13: =VLOOKUP(Tabelle4[[#This Row],[Key]],'3. Unique Results'!A:X,6,FALSE) -> 2021 IEEE International Parallel and Distributed Processing Symposium (IPDPS) | G13: =VLOOKUP(Tabelle4[[#This Row],[Key]],'3. Unique Results'!A:X,7,FALSE) | H13: =VLOOKUP(Tabelle4[[#This Row],[Key]],'3. Unique Results'!A:X,8,FALSE) | I13: =VLOOKUP(Tabelle4[[#This Row],[Key]],'3. Unique Results'!A:X,9,FALSE) -> 10.1109/IPDPS49936.2021.00077 | J13: =VLOOKUP(Tabelle4[[#This Row],[Key]],'3. Unique Results'!A:X,10,FALSE) | K13: =VLOOKUP(Tabelle4[[#This Row],[Key]],'3. Unique Results'!A:X,11,FALSE) -> 2021 | L13: =VLOOKUP(Tabelle4[[#This Row],[Key]],'3. Unique Results'!A:X,12,FALSE) -> 44887.364 | M13: =VLOOKUP(Tabelle4[[#This Row],[Key]],'3. Unique Results'!A:X,13,FALSE) -> 44887.364 | N13: =VLOOKUP(Tabelle4[[#This Row],[Key]],'3. Unique Results'!A:X,14,FALSE) -> 0 | O13: =VLOOKUP(Tabelle4[[#This Row],[Key]],'3. Unique Results'!A:X,15,FALSE) -> 682-682 | P13: =VLOOKUP(Tabelle4[[#This Row],[Key]],'3. Unique Results'!A:X,16,FALSE) | Q13: =VLOOKUP(Tabelle4[[#This Row],[Key]],'3. Unique Results'!A:X,17,FALSE) | R13: =VLOOKUP(Tabelle4[[#This Row],[Key]],'3. Unique Results'!A:X,18,FALSE) | S13: =VLOOKUP(Tabelle4[[#This Row],[Key]],'3. Unique Results'!A:X,19,FALSE) | T13: =VLOOKUP(Tabelle4[[#This Row],[Key]],'3. Unique Results'!A:X,20,FALSE) | U13: =VLOOKUP(Tabelle4[[#This Row],[Key]],'3. Unique Results'!A:X,21,FALSE) | V13: =VLOOKUP(Tabelle4[[#This Row],[Key]],'3. Unique Results'!A:X,22,FALSE) | W13: =VLOOKUP(Tabelle4[[#This Row],[Key]],'3. Unique Results'!A:X,23,FALSE)
... A92: 227PU6N9 | B92: =VLOOKUP(Tabelle4[[#This Row],[Key]],'3. Unique Results'!A:X,2,FALSE) -> #N/A | C92: =VLOOKUP(Tabelle4[[#This Row],[Key]],'3. Unique Results'!A:X,3,FALSE) -> #N/A | D92: =VLOOKUP(Tabelle4[[#This Row],[Key]],'3. Unique Results'!A:X,4,FALSE) -> #N/A | E92: =VLOOKUP(Tabelle4[[#This Row],[Key]],'3. Unique Results'!A:X,5,FALSE) -> #N/A | F92: =VLOOKUP(Tabelle4[[#This Row],[Key]],'3. Unique Results'!A:X,6,FALSE) -> #N/A | G92: =VLOOKUP(Tabelle4[[#This Row],[Key]],'3. Unique Results'!A:X,7,FALSE) -> #N/A | H92: =VLOOKUP(Tabelle4[[#This Row],[Key]],'3. Unique Results'!A:X,8,FALSE) -> #N/A | I92: =VLOOKUP(Tabelle4[[#This Row],[Key]],'3. Unique Results'!A:X,9,FALSE) -> #N/A | J92: =VLOOKUP(Tabelle4[[#This Row],[Key]],'3. Unique Results'!A:X,10,FALSE) -> #N/A | K92: =VLOOKUP(Tabelle4[[#This Row],[Key]],'3. Unique Results'!A:X,11,FALSE) -> #N/A | L92: =VLOOKUP(Tabelle4[[#This Row],[Key]],'3. Unique Results'!A:X,12,FALSE) -> #N/A | M92: =VLOOKUP(Tabelle4[[#This Row],[Key]],'3. Unique Results'!A:X,13,FALSE) -> #N/A | N92: =VLOOKUP(Tabelle4[[#This Row],[Key]],'3. Unique Results'!A:X,14,FALSE) -> #N/A | O92: =VLOOKUP(Tabelle4[[#This Row],[Key]],'3. Unique Results'!A:X,15,FALSE) -> #N/A | P92: =VLOOKUP(Tabelle4[[#This Row],[Key]],'3. Unique Results'!A:X,16,FALSE) -> #N/A | Q92: =VLOOKUP(Tabelle4[[#This Row],[Key]],'3. Unique Results'!A:X,17,FALSE) -> #N/A | R92: =VLOOKUP(Tabelle4[[#This Row],[Key]],'3. Unique Results'!A:X,18,FALSE) -> #N/A | S92: =VLOOKUP(Tabelle4[[#This Row],[Key]],'3. Unique Results'!A:X,19,FALSE) -> #N/A | T92: =VLOOKUP(Tabelle4[[#This Row],[Key]],'3. Unique Results'!A:X,20,FALSE) -> #N/A | U92: =VLOOKUP(Tabelle4[[#This Row],[Key]],'3. Unique Results'!A:X,21,FALSE) -> #N/A | V92: =VLOOKUP(Tabelle4[[#This Row],[Key]],'3. Unique Results'!A:X,22,FALSE) -> #N/A | W92: =VLOOKUP(Tabelle4[[#This Row],[Key]],'3. Unique Results'!A:X,23,FALSE) -> #N/A

Sheet 5. Selection Based on Abstract
A1: Key | B1: Item Type | C1: Publication Year | D1: Author | E1: Title | F1: Publication Title | G1: ISBN | H1: ISSN | I1: DOI | J1: Url | K1: Abstract Note | L1: Date | M1: Date Added | N1: Date Modified | O1: Access Date | P1: Pages | Q1: Num Pages | R1: Issue | S1: Volume | T1: Series | U1: Publisher | V1: Place | W1: Extra
A2: UCWWRPIQ | B2: =VLOOKUP(Tabelle43[[#This Row],[Key]],'3. Unique Results'!A:X,2,FALSE) -> conferencePaper | C2: =VLOOKUP(Tabelle43[[#This Row],[Key]],'3. Unique Results'!A:X,3,FALSE) -> 2020 | D2: =VLOOKUP(Tabelle43[[#This Row],[Key]],'3. Unique Results'!A:X,4,FALSE) -> Al-Azzoni, Issam | E2: =VLOOKUP(Tabelle43[[#This Row],[Key]],'3. Unique Results'!A:X,5,FALSE) -> Model Driven Approach for Neural Networks | F2: =VLOOKUP(Tabelle43[[#This Row],[Key]],'3. Unique Results'!A:X,6,FALSE) -> 2020 International Conference on Intelligent Data Science Technologies and Applications (IDSTA) | G2: =VLOOKUP(Tabelle43[[#This Row],[Key]],'3. Unique Results'!A:X,7,FALSE) | H2: =VLOOKUP(Tabelle43[[#This Row],[Key]],'3. Unique Results'!A:X,8,FALSE) | I2: =VLOOKUP(Tabelle43[[#This Row],[Key]],'3. Unique Results'!A:X,9,FALSE) -> 10.1109/IDSTA50958.2020.9264067 | J2: =VLOOKUP(Tabelle43[[#This Row],[Key]],'3. Unique Results'!A:X,10,FALSE) | K2: =VLOOKUP(Tabelle43[[#This Row],[Key]],'3. Unique Results'!A:X,11,FALSE) -> 2020 | L2: =VLOOKUP(Tabelle43[[#This Row],[Key]],'3. Unique Results'!A:X,12,FALSE) -> 44887.364 | M2: =VLOOKUP(Tabelle43[[#This Row],[Key]],'3. Unique Results'!A:X,13,FALSE) -> 44887.364 | N2: =VLOOKUP(Tabelle43[[#This Row],[Key]],'3. Unique Results'!A:X,14,FALSE) -> 0 | O2: =VLOOKUP(Tabelle43[[#This Row],[Key]],'3. Unique Results'!A:X,15,FALSE) -> 87-94 | P2: =VLOOKUP(Tabelle43[[#This Row],[Key]],'3. Unique Results'!A:X,16,FALSE) | Q2: =VLOOKUP(Tabelle43[[#This Row],[Key]],'3. Unique Results'!A:X,17,FALSE) | R2: =VLOOKUP(Tabelle43[[#This Row],[Key]],'3. Unique Results'!A:X,18,FALSE) | S2: =VLOOKUP(Tabelle43[[#This Row],[Key]],'3. Unique Results'!A:X,19,FALSE) | T2: =VLOOKUP(Tabelle43[[#This Row],[Key]],'3. Unique Results'!A:X,20,FALSE) | U2: =VLOOKUP(Tabelle43[[#This Row],[Key]],'3. Unique Results'!A:X,21,FALSE) | V2: =VLOOKUP(Tabelle43[[#This Row],[Key]],'3. Unique Results'!A:X,22,FALSE) | W2: =VLOOKUP(Tabelle43[[#This Row],[Key]],'3. Unique Results'!A:X,23,FALSE)
